Workbook

Sheet Rà soát
A1: RÀ SOÁT KẾ HOẠCH VÀ CÁC ĐIỀU CHỈNH
A2: Đã đối chiếu 216 task với 39 FR, 23 NFR và các yêu cầu bắt buộc (Confluence, GitHub, Jira, SOA, Microservice, Docker, NiFi, Firebase, API Gateway). Cột 'Áp dụng ở' trỏ tới task đã sửa trong sheet 'Task 8 tuần'.
A4: # | B4: Mức độ | C4: Vấn đề phát hiện | D4: Cách khắc phục | E4: Áp dụng ở (ID task)
A5: 1 | B5: Cao | C5: HTTPS và tên miền để tới tuần 5. Nhưng FCM trên web (service worker) cần HTTPS từ tuần 4 và VNPay cần URL callback công khai từ tuần 5. | D5: Chuyển tên miền + Let's Encrypt sang tuần 2 trong task dựng VPS staging. Tuần 5 chỉ còn cứng hóa TLS (HSTS) và mã hóa PII. | E5: W2-M1-4, W5-M1-1
A6: 2 | B6: Cao | C6: Thiếu màn hình frontend cho nhiều FR: hồ sơ cá nhân (FR-8), đăng ký clinic (FR-22), thống kê bác sĩ (FR-21), giám sát và báo cáo clinic (FR-25,26,27,29), cấu hình AI (FR-33), xem audit (FR-37), biểu đồ xu hướng (FR-17), nút tải báo cáo (FR-7), form feedback AI (FR-19). API có nhưng người dùng không thao tác được. | D6: Thêm task UI cụ thể cho từng màn hình ở tuần 2, 4, 5, 6. | E6: W2-M5-5, W4-M5-3..5, W5-M5-2..5, W6-M5-2..3
A7: 3 | B7: Cao | C7: M5 là người duy nhất làm frontend cho 4 cổng (Patient, Doctor, Clinic, Admin), quá tải ở tuần 5–6 và là nút thắt. | D7: Áp dụng 'sở hữu dọc': người làm API cũng làm UI đơn giản (form, bảng) của chính nó. M1 làm UI quản lý tài khoản, M2 làm UI thống kê bác sĩ, M3 làm UI chat và form gói/template. M5 giữ màn phức tạp, design system, responsive. | E7: W5-M3-4, W6-M1-1, W6-M2-1, W6-M3-5
A8: 4 | B8: Cao | C8: Dataset công khai (APTOS, DRIVE...) không có nhãn tăng huyết áp, biến chứng tiểu đường hay đột quỵ. Nếu trình bày điểm nguy cơ như kết quả lâm sàng thì sai về mặt khoa học và sẽ bị hội đồng hỏi vặn. | D8: Risk score là heuristic dựa trên chỉ số mạch và quy tắc cấu hình được. Ghi rõ 'không phải chẩn đoán' trên giao diện, báo cáo PDF và Model card. Đề tài đã định vị AURA là hỗ trợ bác sĩ. | E8: W1-M4-6, W3-M4-2, W6-M4-2, W7-M4-2
A9: 5 | B9: Trung bình | C9: FR-2 cho phép ảnh OCT, nhưng mô hình chỉ xử lý ảnh đáy mắt (Fundus). | D9: Chốt quy tắc: hệ thống nhận cả OCT, gắn cờ 'chưa hỗ trợ phân tích AI'; AI trả mã 'unsupported' cho OCT. | E9: W1-M2-1, W2-M4-1, W3-M2-2
A10: 6 | B10: Cao | C10: Dashboard Admin (FR-35,36) cần số liệu từ nhiều service. Nếu truy vấn thẳng DB chéo service thì vi phạm nguyên tắc microservice (mỗi service một DB). | D10: Thêm service thứ 8 là analytics-svc, dữ liệu được NiFi flow #3 (ETL) đẩy vào. Thống nhất schema đích từ Thứ Hai tuần 6. | E10: W6-M3-3, W6-M4-1
A11: 7 | B11: Cao | C11: Cả stack (7 service .NET, AI, NiFi, Postgres, Mongo, RabbitMQ, Seq) trên một VPS nhỏ sẽ hết RAM. NiFi một mình cần khoảng 2GB. | D11: VPS khuyến nghị tối thiểu 8 vCPU / 16GB RAM. AI chạy CPU bằng ONNX, giới hạn RAM từng container, đo từ tuần 2. Có thể dùng Supabase Postgres để nhẹ VPS. | E11: W1-M1-5, W2-M1-4, W2-M4-4
A12: 8 | B12: Trung bình | C12: FR-1 chỉ ghi đăng ký và đăng nhập, nhưng hệ thống chạy thật cần quên mật khẩu và xác minh email. | D12: Thêm task quên/đặt lại mật khẩu và xác minh email ở tuần 2. | E12: W2-M2-4, W2-M5-2
A13: 9 | B13: Cao | C13: Ảnh y tế lưu trên Cloudinary có thể bị truy cập qua URL công khai, trái NFR-9 và NFR-10. Ảnh có thể chứa EXIF/PII. | D13: Dùng ảnh private với signed URL, xóa EXIF khi tải lên và khi ẩn danh dữ liệu retrain. | E13: W5-M1-4, W5-M4-1
A14: 10 | B14: Trung bình | C14: NFR-20 yêu cầu 'định dạng y khoa chuẩn nếu có thể' nhưng kế hoạch cũ chỉ có PDF/CSV. | D14: Thêm xuất FHIR DiagnosticReport (JSON) ở tuần 4. | E14: W4-M1-2
A15: 11 | B15: Trung bình | C15: NFR-18 (log tập trung) chưa bao gồm service Python AI. | D15: Task Seq ở tuần 4 gồm cả log AI Core. | E15: W4-M1-5
A16: 12 | B16: Trung bình | C16: NFR-4 (uptime ≥99%) chưa có công cụ giám sát. | D16: Thêm giám sát uptime và cảnh báo ở tuần 5, kiểm tra ở tuần 7. | E16: W5-M1-5, W7-M1-4
... A20: 16 | B20: Xác nhận | C20: Tổng giờ mỗi người mỗi tuần. | D20: Đã kiểm lại: 40/40 ô người-tuần đều đúng 52 giờ, tổng 416 giờ/người (xem sheet 'Tổng giờ'). | E20: Tổng giờ
A22: Những điểm hệ thống KHÔNG đạt hoặc chỉ ở mức mô phỏng (cần nói thẳng khi bảo vệ)
B23: Điểm nguy cơ AI là heuristic để minh họa luồng phần mềm, chưa được kiểm chứng lâm sàng.
B24: Tích hợp máy chụp đáy mắt thật được mô phỏng bằng NiFi (thư mục/HTTP/SFTP), chưa nối thiết bị thật.
B25: Thanh toán chạy trên VNPay sandbox, không phải tiền thật.
B26: Ứng dụng mobile Flutter không làm (đề tài ghi optional).
B27: Chuẩn HIPAA-like được thể hiện bằng kiểm soát kỹ thuật (mã hóa, RBAC, audit), chưa có chứng nhận tuân thủ.

Sheet Task 8 tuần
A1: ID | B1: Tuần | C1: Người | D1: Tên task (Jira Summary) | E1: Epic | F1: Giờ | G1: FR/NFR liên quan | H1: Cần trước (đầu vào) | I1: Tiêu chí hoàn thành | J1: Sprint | K1: Labels | L1: _ref
A2: W1-M1-1 | B2: 1 | C2: M1 | D2: [W1][M1] Tạo Jira: workflow, board, sprint 1→8 | E2: E1 - Platform/DevOps | F2: 6 | H2: — | I2: Board đủ 5 cột; 8 sprint; bật Original estimate/Log work; đủ 5 thành viên | J2: Sprint 1 - Nền móng | K2: W1 M1 | L2: ,,
A3: W1-M1-2 | B3: 1 | C3: M1 | D3: [W1][M1] GitHub monorepo, branch protection, CODEOWNERS, PR template, CI khung | E3: E1 - Platform/DevOps | F3: 8 | G3: NFR-17 | H3: — | I3: Không push thẳng main/develop; PR cần 1 review; CI chạy trên mỗi PR | J3: Sprint 1 - Nền móng | K3: W1 M1 | L3: ,NFR-17,
A4: W1-M1-3 | B4: 1 | C4: M1 | D4: [W1][M1] Confluence space, template, DoD | E4: E14 - Documentation | F4: 5 | H4: — | I4: Cây 7 thư mục; template trang; DoD đã đăng và cả nhóm đã đọc | J4: Sprint 1 - Nền móng | K4: W1 M1 | L4: ,,
A5: W1-M1-4 | B5: 1 | C5: M1 | D5: [W1][M1] Architecture v0.1: sơ đồ SOA/microservice, ranh giới service, ADR 001→010 | E5: E14 - Documentation | F5: 14 | G5: NFR-7,NFR-17 | H5: — | I5: Sơ đồ + 10 ADR trên Confluence, nhóm thống nhất | J5: Sprint 1 - Nền móng | K5: W1 M1 | L5: ,NFR-7,NFR-17,
A6: W1-M1-5 | B6: 1 | C6: M1 | D6: [W1][M1] docker-compose hạ tầng: Postgres, Mongo, RabbitMQ, NiFi | E6: E1 - Platform/DevOps | F6: 10 | G6: NFR-7 | H6: — | I6: docker compose up chạy đủ 4 thành phần; ghi rõ RAM tối thiểu VPS (khuyến nghị 16GB) | J6: Sprint 1 - Nền móng | K6: W1 M1 | L6: ,NFR-7,
A7: W1-M1-6 | B7: 1 | C7: M1 | D7: [W1][M1] Template service .NET (Clean Architecture, health check, Serilog, Swagger, Dockerfile) | E7: E1 - Platform/DevOps | F7: 9 | G7: NFR-17 | H7: — | I7: Clone về chạy được trong 10 phút; có /health, Swagger, Dockerfile | J7: Sprint 1 - Nền móng | K7: W1 M1 | L7: ,NFR-17,
A8: W1-M2-1 | B8: 1 | C8: M2 | D8: [W1][M2] Glossary và domain model | E8: E14 - Documentation | F8: 8 | H8: — | I8: ≥30 thuật ngữ; chốt quy tắc OCT (nhận upload, chỉ Fundus được AI chấm) | J8: Sprint 1 - Nền móng | K8: W1 M2 | L8: ,,
A9: W1-M2-2 | B9: 1 | C9: M2 | D9: [W1][M2] Use case spec Patient, Doctor (FR-1→21) | E9: E14 - Documentation | F9: 14 | G9: FR-1:21 | H9: — | I9: Mỗi FR có use case, luồng chính, luồng ngoại lệ | J9: Sprint 1 - Nền móng | K9: W1 M2 | L9: ,FR-1,FR-2,FR-3,FR-4,FR-5,FR-6,FR-7,FR-8,FR-9,FR-10,FR-11,FR-12,FR-13,FR-14,FR-15,FR-16,FR-17,FR-18,FR-19,FR-20,FR-21,
A10: W1-M2-3 | B10: 1 | C10: M2 | D10: [W1][M2] Class diagram miền v0.1 | E10: E14 - Documentation | F10: 10 | H10: — | I10: Account kế thừa 4 vai trò; Clinic, Analysis, Review, Report; đúng UML 2.0 | J10: Sprint 1 - Nền móng | K10: W1 M2 | L10: ,,
A11: W1-M2-4 | B11: 1 | C11: M2 | D11: [W1][M2] State diagram AnalysisRequest + Activity diagram luồng sàng lọc | E11: E4 - Analysis Pipeline | F11: 8 | G11: FR-24 | H11: — | I11: Đủ trạng thái Pending→Processing→AIDone→Reviewed→Finalized/Failed | J11: Sprint 1 - Nền móng | K11: W1 M2 | L11: ,FR-24,
A12: W1-M2-5 | B12: 1 | C12: M2 | D12: [W1][M2] ERD Profile/Analysis | E12: E4 - Analysis Pipeline | F12: 12 | H12: — | I12: Schema tách theo service, không khóa ngoại chéo service | J12: Sprint 1 - Nền móng | K12: W1 M2 | L12: ,,
A13: W1-M3-1 | B13: 1 | C13: M3 | D13: [W1][M3] Chuẩn hóa FR/NFR, sửa lỗi FR-30, ma trận truy vết, MoSCoW | E13: E14 - Documentation | F13: 10 | G13: FR-30 | H13: — | I13: Ma trận FR/NFR↔task; FR-30 ghi đúng; phân loại Must/Should/Could | J13: Sprint 1 - Nền móng | K13: W1 M3 | L13: ,FR-30,
A14: W1-M3-2 | B14: 1 | C14: M3 | D14: [W1][M3] Use case spec Clinic, Admin (FR-22→39) | E14: E14 - Documentation | F14: 14 | G14: FR-22:39 | H14: — | I14: Mỗi FR có use case | J14: Sprint 1 - Nền móng | K14: W1 M3 | L14: ,FR-22,FR-23,FR-24,FR-25,FR-26,FR-27,FR-28,FR-29,FR-30,FR-31,FR-32,FR-33,FR-34,FR-35,FR-36,FR-37,FR-38,FR-39,
A15: W1-M3-3 | B15: 1 | C15: M3 | D15: [W1][M3] Tạo toàn bộ backlog Jira: epic, story, tiêu chí chấp nhận, ước lượng | E15: E14 - Documentation | F15: 14 | H15: Use case Patient/Doctor (M2, Thứ Tư) | I15: Story cho 39 FR kèm AC; import từ file kế hoạch này | J15: Sprint 1 - Nền móng | K15: W1 M3 | L15: ,,
A16: W1-M3-4 | B16: 1 | C16: M3 | D16: [W1][M3] Test plan khung, tiêu chí đo cho NFR | E16: E13 - Testing | F16: 6 | G16: NFR-1:23 | H16: — | I16: Mỗi NFR có cách đo và ngưỡng đạt | J16: Sprint 1 - Nền móng | K16: W1 M3 | L16: ,NFR-1,NFR-2,NFR-3,NFR-4,NFR-5,NFR-6,NFR-7,NFR-8,NFR-9,NFR-10,NFR-11,NFR-12,NFR-13,NFR-14,NFR-15,NFR-16,NFR-17,NFR-18,NFR-19,NFR-20,NFR-21,NFR-22,NFR-23,
A17: W1-M3-5 | B17: 1 | C17: M3 | D17: [W1][M3] Domain Billing/Notification + ERD | E17: E14 - Documentation | F17: 8 | H17: — | I17: ERD hai service; không FK chéo | J17: Sprint 1 - Nền móng | K17: W1 M3 | L17: ,,
A18: W1-M4-1 | B18: 1 | C18: M4 | D18: [W1][M4] Tải dataset (APTOS/DRIVE), EDA | E18: E5 - AI Core | F18: 8 | H18: — | I18: Báo cáo EDA; ghi rõ dataset nào có nhãn gì | J18: Sprint 1 - Nền móng | K18: W1 M4 | L18: ,,
A19: W1-M4-2 | B19: 1 | C19: M4 | D19: [W1][M4] Notebook suy luận cơ sở: phân vùng mạch + phân loại | E19: E5 - AI Core | F19: 16 | G19: FR-3 | H19: — | I19: Chạy được trên ≥20 ảnh mẫu, lưu kết quả | J19: Sprint 1 - Nền móng | K19: W1 M4 | L19: ,FR-3,
A20: W1-M4-3 | B20: 1 | C20: M4 | D20: [W1][M4] Hợp đồng API AI (OpenAPI v0.1) | E20: E5 - AI Core | F20: 6 | G20: NFR-21 | H20: — | I20: M1, M2 duyệt hợp đồng; input/output JSON cố định | J20: Sprint 1 - Nền móng | K20: W1 M4 | L20: ,NFR-21,
A21: W1-M4-4 | B21: 1 | C21: M4 | D21: [W1][M4] Khung FastAPI + Dockerfile | E21: E5 - AI Core | F21: 8 | G21: NFR-21 | H21: — | I21: Container chạy, /health và /analyze (mock) trả JSON | J21: Sprint 1 - Nền móng | K21: W1 M4 | L21: ,NFR-21,
A22: W1-M4-5 | B22: 1 | C22: M4 | D22: [W1][M4] Dựng NiFi, flow hello | E22: E9 - NiFi Integration | F22: 8 | H22: — | I22: NiFi UI truy cập được, flow ListenHTTP→log chạy | J22: Sprint 1 - Nền móng | K22: W1 M4 | L22: ,,
A23: W1-M4-6 | B23: 1 | C23: M4 | D23: [W1][M4] Báo cáo khả thi AI (độ chính xác, thời gian suy luận) | E23: E5 - AI Core | F23: 6 | G23: NFR-1 | H23: — | I23: Có số liệu; nêu rõ risk score là heuristic vì dataset công khai không có nhãn tăng huyết áp/đột quỵ | J23: Sprint 1 - Nền móng | K23: W1 M4 | L23: ,NFR-1,
A24: W1-M5-1 | B24: 1 | C24: M5 | D24: [W1][M5] Persona + sitemap theo 4 vai trò | E24: E12 - Frontend | F24: 6 | G24: NFR-13 | H24: — | I24: Sitemap 4 vai trò được nhóm duyệt | J24: Sprint 1 - Nền móng | K24: W1 M5 | L24: ,NFR-13,
A25: W1-M5-2 | B25: 1 | C25: M5 | D25: [W1][M5] Wireframe Figma Patient + Doctor | E25: E12 - Frontend | F25: 16 | G25: FR-1:21 | H25: — | I25: Phủ mọi màn của FR-1→21 | J25: Sprint 1 - Nền móng | K25: W1 M5 | L25: ,FR-1,FR-2,FR-3,FR-4,FR-5,FR-6,FR-7,FR-8,FR-9,FR-10,FR-11,FR-12,FR-13,FR-14,FR-15,FR-16,FR-17,FR-18,FR-19,FR-20,FR-21,
A26: W1-M5-3 | B26: 1 | C26: M5 | D26: [W1][M5] Wireframe Clinic + Admin | E26: E12 - Frontend | F26: 10 | G26: FR-22:39 | H26: — | I26: Phủ mọi màn của FR-22→39 | J26: Sprint 1 - Nền móng | K26: W1 M5 | L26: ,FR-22,FR-23,FR-24,FR-25,FR-26,FR-27,FR-28,FR-29,FR-30,FR-31,FR-32,FR-33,FR-34,FR-35,FR-36,FR-37,FR-38,FR-39,
A27: W1-M5-4 | B27: 1 | C27: M5 | D27: [W1][M5] Design system: màu, typography, component | E27: E12 - Frontend | F27: 8 | G27: NFR-13,NFR-15 | H27: — | I27: Bảng màu, font, component cơ bản trên Figma | J27: Sprint 1 - Nền móng | K27: W1 M5 | L27: ,NFR-13,NFR-15,
A28: W1-M5-5 | B28: 1 | C28: M5 | D28: [W1][M5] Scaffold React + TS (Vite, router, ESLint, UI lib, CI) | E28: E12 - Frontend | F28: 12 | G28: NFR-17 | H28: Repo (M1, ngày 1-2) | I28: npm run dev chạy; CI lint+build xanh | J28: Sprint 1 - Nền móng | K28: W1 M5 | L28: ,NFR-17,
A29: W2-M1-1 | B29: 2 | C29: M1 | D29: [W2][M1] YARP Gateway: route, xác thực JWT, rate limit, CORS, correlation-id | E29: E2 - Identity & Gateway | F29: 16 | G29: NFR-12,NFR-21 | H29: Khóa ký JWT dev (M2, Thứ Ba) | I29: Không token→401; có token→200; log có X-Correlation-Id | J29: Sprint 2 - Gateway, Identity, Profile, AI v0.1 | K29: W2 M1 | L29: ,NFR-12,NFR-21,
A30: W2-M1-2 | B30: 2 | C30: M1 | D30: [W2][M1] Thư viện dùng chung: exception middleware, logging, phân trang, response envelope | E30: E1 - Platform/DevOps | F30: 8 | G30: NFR-17,NFR-18 | H30: Template service (T1) | I30: ≥3 service dùng chung thư viện | J30: Sprint 2 - Gateway, Identity, Profile, AI v0.1 | K30: W2 M1 | L30: ,NFR-17,NFR-18,
A31: W2-M1-3 | B31: 2 | C31: M1 | D31: [W2][M1] CI: build + test + docker build + đẩy GHCR | E31: E1 - Platform/DevOps | F31: 10 | G31: NFR-17 | H31: Template service (T1) | I31: PR chạy build+test; merge develop đẩy image lên GHCR | J31: Sprint 2 - Gateway, Identity, Profile, AI v0.1 | K31: W2 M1 | L31: ,NFR-17,
A32: W2-M1-4 | B32: 2 | C32: M1 | D32: [W2][M1] VPS staging: Docker Compose + Nginx + tên miền + HTTPS Let's Encrypt | E32: E1 - Platform/DevOps | F32: 14 | G32: NFR-9 | H32: — | I32: https://<domain>/health trả 200, chứng chỉ hợp lệ (FCM và VNPay cần HTTPS công khai); VPS ≥16GB RAM | J32: Sprint 2 - Gateway, Identity, Profile, AI v0.1 | K32: W2 M1 | L32: ,NFR-9,
A33: W2-M1-5 | B33: 2 | C33: M1 | D33: [W2][M1] Gom Swagger + Postman collection | E33: E1 - Platform/DevOps | F33: 4 | G33: NFR-21 | H33: — | I33: Một collection gọi được Identity, Profile qua Gateway | J33: Sprint 2 - Gateway, Identity, Profile, AI v0.1 | K33: W2 M1 | L33: ,NFR-21,
A34: W2-M2-1 | B34: 2 | C34: M2 | D34: [W2][M2] Identity: đăng ký/đăng nhập email, JWT + refresh token | E34: E2 - Identity & Gateway | F34: 16 | G34: FR-1 | H34: — | I34: Đăng ký→đăng nhập→JWT; refresh hoạt động; mật khẩu băm | J34: Sprint 2 - Gateway, Identity, Profile, AI v0.1 | K34: W2 M2 | L34: ,FR-1,
... A37: W2-M2-4 | B37: 2 | C37: M2 | D37: [W2][M2] Quên/đặt lại mật khẩu + xác minh email | E37: E2 - Identity & Gateway | F37: 6 | G37: FR-1 | H37: — | I37: Nhận email có link; đặt lại được mật khẩu | J37: Sprint 2 - Gateway, Identity, Profile, AI v0.1 | K37: W2 M2 | L37: ,FR-1,
A38: W2-M2-5 | B38: 2 | C38: M2 | D38: [W2][M2] Unit test Identity | E38: E2 - Identity & Gateway | F38: 6 | H38: — | I38: Coverage logic chính ≥70%, CI xanh | J38: Sprint 2 - Gateway, Identity, Profile, AI v0.1 | K38: W2 M2 | L38: ,,
A39: W2-M2-6 | B39: 2 | C39: M2 | D39: [W2][M2] Tài liệu API Identity (OpenAPI + Confluence) | E39: E14 - Documentation | F39: 6 | H39: — | I39: Trang Confluence + Swagger đủ endpoint | J39: Sprint 2 - Gateway, Identity, Profile, AI v0.1 | K39: W2 M2 | L39: ,,
A40: W2-M3-1 | B40: 2 | C40: M3 | D40: [W2][M3] Profile: hồ sơ bệnh nhân CRUD | E40: E3 - Profile & Clinic | F40: 12 | G40: FR-8 | H40: JWT dev (M2) | I40: Tạo/sửa/xem hồ sơ; chỉ chủ hồ sơ truy cập | J40: Sprint 2 - Gateway, Identity, Profile, AI v0.1 | K40: W2 M3 | L40: ,FR-8,
A41: W2-M3-2 | B41: 2 | C41: M3 | D41: [W2][M3] Đăng ký clinic + luồng xác minh | E41: E3 - Profile & Clinic | F41: 12 | G41: FR-22 | H41: — | I41: Clinic đăng ký ở trạng thái Pending chờ duyệt | J41: Sprint 2 - Gateway, Identity, Profile, AI v0.1 | K41: W2 M3 | L41: ,FR-22,
A42: W2-M3-3 | B42: 2 | C42: M3 | D42: [W2][M3] Quản lý bác sĩ/bệnh nhân thuộc clinic | E42: E3 - Profile & Clinic | F42: 12 | G42: FR-23 | H42: — | I42: Clinic thêm/sửa/khóa bác sĩ và bệnh nhân của mình | J42: Sprint 2 - Gateway, Identity, Profile, AI v0.1 | K42: W2 M3 | L42: ,FR-23,
...

Sheet Tổng giờ
A1: TỔNG GIỜ THEO NGƯỜI VÀ TUẦN (tính bằng công thức từ sheet 'Task 8 tuần')
A2: Mục tiêu giờ/người/tuần | B2: 52 | C2: (yêu cầu tối thiểu 400 giờ/người; 52×8 = 416)
A4: Người | B4: Tuần 1 | C4: Tuần 2 | D4: Tuần 3 | E4: Tuần 4 | F4: Tuần 5 | G4: Tuần 6 | H4: Tuần 7 | I4: Tuần 8 | J4: Tổng | K4: Đạt ≥400h? | L4: Mọi tuần = mục tiêu?
A5: M1 | B5: =SUMIFS('Task 8 tuần'!$F$2:$F$217,'Task 8 tuần'!$C$2:$C$217,$A5,'Task 8 tuần'!$B$2:$B$217,1) -> 52 | C5: =SUMIFS('Task 8 tuần'!$F$2:$F$217,'Task 8 tuần'!$C$2:$C$217,$A5,'Task 8 tuần'!$B$2:$B$217,2) -> 52 | D5: =SUMIFS('Task 8 tuần'!$F$2:$F$217,'Task 8 tuần'!$C$2:$C$217,$A5,'Task 8 tuần'!$B$2:$B$217,3) -> 52 | E5: =SUMIFS('Task 8 tuần'!$F$2:$F$217,'Task 8 tuần'!$C$2:$C$217,$A5,'Task 8 tuần'!$B$2:$B$217,4) -> 52 | F5: =SUMIFS('Task 8 tuần'!$F$2:$F$217,'Task 8 tuần'!$C$2:$C$217,$A5,'Task 8 tuần'!$B$2:$B$217,5) -> 52 | G5: =SUMIFS('Task 8 tuần'!$F$2:$F$217,'Task 8 tuần'!$C$2:$C$217,$A5,'Task 8 tuần'!$B$2:$B$217,6) -> 52 | H5: =SUMIFS('Task 8 tuần'!$F$2:$F$217,'Task 8 tuần'!$C$2:$C$217,$A5,'Task 8 tuần'!$B$2:$B$217,7) -> 52 | I5: =SUMIFS('Task 8 tuần'!$F$2:$F$217,'Task 8 tuần'!$C$2:$C$217,$A5,'Task 8 tuần'!$B$2:$B$217,8) -> 52 | J5: =SUM(B5:I5) -> 416 | K5: =IF(J5>=400,"Đạt","Thiếu") -> Đạt | L5: =IF(COUNTIF(B5:I5,$B$2)=8,"Đúng","Lệch") -> Đúng
A6: M2 | B6: =SUMIFS('Task 8 tuần'!$F$2:$F$217,'Task 8 tuần'!$C$2:$C$217,$A6,'Task 8 tuần'!$B$2:$B$217,1) -> 52 | C6: =SUMIFS('Task 8 tuần'!$F$2:$F$217,'Task 8 tuần'!$C$2:$C$217,$A6,'Task 8 tuần'!$B$2:$B$217,2) -> 52 | D6: =SUMIFS('Task 8 tuần'!$F$2:$F$217,'Task 8 tuần'!$C$2:$C$217,$A6,'Task 8 tuần'!$B$2:$B$217,3) -> 52 | E6: =SUMIFS('Task 8 tuần'!$F$2:$F$217,'Task 8 tuần'!$C$2:$C$217,$A6,'Task 8 tuần'!$B$2:$B$217,4) -> 52 | F6: =SUMIFS('Task 8 tuần'!$F$2:$F$217,'Task 8 tuần'!$C$2:$C$217,$A6,'Task 8 tuần'!$B$2:$B$217,5) -> 52 | G6: =SUMIFS('Task 8 tuần'!$F$2:$F$217,'Task 8 tuần'!$C$2:$C$217,$A6,'Task 8 tuần'!$B$2:$B$217,6) -> 52 | H6: =SUMIFS('Task 8 tuần'!$F$2:$F$217,'Task 8 tuần'!$C$2:$C$217,$A6,'Task 8 tuần'!$B$2:$B$217,7) -> 52 | I6: =SUMIFS('Task 8 tuần'!$F$2:$F$217,'Task 8 tuần'!$C$2:$C$217,$A6,'Task 8 tuần'!$B$2:$B$217,8) -> 52 | J6: =SUM(B6:I6) -> 416 | K6: =IF(J6>=400,"Đạt","Thiếu") -> Đạt | L6: =IF(COUNTIF(B6:I6,$B$2)=8,"Đúng","Lệch") -> Đúng
A7: M3 | B7: =SUMIFS('Task 8 tuần'!$F$2:$F$217,'Task 8 tuần'!$C$2:$C$217,$A7,'Task 8 tuần'!$B$2:$B$217,1) -> 52 | C7: =SUMIFS('Task 8 tuần'!$F$2:$F$217,'Task 8 tuần'!$C$2:$C$217,$A7,'Task 8 tuần'!$B$2:$B$217,2) -> 52 | D7: =SUMIFS('Task 8 tuần'!$F$2:$F$217,'Task 8 tuần'!$C$2:$C$217,$A7,'Task 8 tuần'!$B$2:$B$217,3) -> 52 | E7: =SUMIFS('Task 8 tuần'!$F$2:$F$217,'Task 8 tuần'!$C$2:$C$217,$A7,'Task 8 tuần'!$B$2:$B$217,4) -> 52 | F7: =SUMIFS('Task 8 tuần'!$F$2:$F$217,'Task 8 tuần'!$C$2:$C$217,$A7,'Task 8 tuần'!$B$2:$B$217,5) -> 52 | G7: =SUMIFS('Task 8 tuần'!$F$2:$F$217,'Task 8 tuần'!$C$2:$C$217,$A7,'Task 8 tuần'!$B$2:$B$217,6) -> 52 | H7: =SUMIFS('Task 8 tuần'!$F$2:$F$217,'Task 8 tuần'!$C$2:$C$217,$A7,'Task 8 tuần'!$B$2:$B$217,7) -> 52 | I7: =SUMIFS('Task 8 tuần'!$F$2:$F$217,'Task 8 tuần'!$C$2:$C$217,$A7,'Task 8 tuần'!$B$2:$B$217,8) -> 52 | J7: =SUM(B7:I7) -> 416 | K7: =IF(J7>=400,"Đạt","Thiếu") -> Đạt | L7: =IF(COUNTIF(B7:I7,$B$2)=8,"Đúng","Lệch") -> Đúng
A8: M4 | B8: =SUMIFS('Task 8 tuần'!$F$2:$F$217,'Task 8 tuần'!$C$2:$C$217,$A8,'Task 8 tuần'!$B$2:$B$217,1) -> 52 | C8: =SUMIFS('Task 8 tuần'!$F$2:$F$217,'Task 8 tuần'!$C$2:$C$217,$A8,'Task 8 tuần'!$B$2:$B$217,2) -> 52 | D8: =SUMIFS('Task 8 tuần'!$F$2:$F$217,'Task 8 tuần'!$C$2:$C$217,$A8,'Task 8 tuần'!$B$2:$B$217,3) -> 52 | E8: =SUMIFS('Task 8 tuần'!$F$2:$F$217,'Task 8 tuần'!$C$2:$C$217,$A8,'Task 8 tuần'!$B$2:$B$217,4) -> 52 | F8: =SUMIFS('Task 8 tuần'!$F$2:$F$217,'Task 8 tuần'!$C$2:$C$217,$A8,'Task 8 tuần'!$B$2:$B$217,5) -> 52 | G8: =SUMIFS('Task 8 tuần'!$F$2:$F$217,'Task 8 tuần'!$C$2:$C$217,$A8,'Task 8 tuần'!$B$2:$B$217,6) -> 52 | H8: =SUMIFS('Task 8 tuần'!$F$2:$F$217,'Task 8 tuần'!$C$2:$C$217,$A8,'Task 8 tuần'!$B$2:$B$217,7) -> 52 | I8: =SUMIFS('Task 8 tuần'!$F$2:$F$217,'Task 8 tuần'!$C$2:$C$217,$A8,'Task 8 tuần'!$B$2:$B$217,8) -> 52 | J8: =SUM(B8:I8) -> 416 | K8: =IF(J8>=400,"Đạt","Thiếu") -> Đạt | L8: =IF(COUNTIF(B8:I8,$B$2)=8,"Đúng","Lệch") -> Đúng
A9: M5 | B9: =SUMIFS('Task 8 tuần'!$F$2:$F$217,'Task 8 tuần'!$C$2:$C$217,$A9,'Task 8 tuần'!$B$2:$B$217,1) -> 52 | C9: =SUMIFS('Task 8 tuần'!$F$2:$F$217,'Task 8 tuần'!$C$2:$C$217,$A9,'Task 8 tuần'!$B$2:$B$217,2) -> 52 | D9: =SUMIFS('Task 8 tuần'!$F$2:$F$217,'Task 8 tuần'!$C$2:$C$217,$A9,'Task 8 tuần'!$B$2:$B$217,3) -> 52 | E9: =SUMIFS('Task 8 tuần'!$F$2:$F$217,'Task 8 tuần'!$C$2:$C$217,$A9,'Task 8 tuần'!$B$2:$B$217,4) -> 52 | F9: =SUMIFS('Task 8 tuần'!$F$2:$F$217,'Task 8 tuần'!$C$2:$C$217,$A9,'Task 8 tuần'!$B$2:$B$217,5) -> 52 | G9: =SUMIFS('Task 8 tuần'!$F$2:$F$217,'Task 8 tuần'!$C$2:$C$217,$A9,'Task 8 tuần'!$B$2:$B$217,6) -> 52 | H9: =SUMIFS('Task 8 tuần'!$F$2:$F$217,'Task 8 tuần'!$C$2:$C$217,$A9,'Task 8 tuần'!$B$2:$B$217,7) -> 52 | I9: =SUMIFS('Task 8 tuần'!$F$2:$F$217,'Task 8 tuần'!$C$2:$C$217,$A9,'Task 8 tuần'!$B$2:$B$217,8) -> 52 | J9: =SUM(B9:I9) -> 416 | K9: =IF(J9>=400,"Đạt","Thiếu") -> Đạt | L9: =IF(COUNTIF(B9:I9,$B$2)=8,"Đúng","Lệch") -> Đúng
A10: Cả nhóm | B10: =SUM(B5:B9) -> 260 | C10: =SUM(C5:C9) -> 260 | D10: =SUM(D5:D9) -> 260 | E10: =SUM(E5:E9) -> 260 | F10: =SUM(F5:F9) -> 260 | G10: =SUM(G5:G9) -> 260 | H10: =SUM(H5:H9) -> 260 | I10: =SUM(I5:I9) -> 260 | J10: =SUM(J5:J9) -> 2080
A12: Số task mỗi tuần | B12: =COUNTIF('Task 8 tuần'!$B$2:$B$217,1) -> 27 | C12: =COUNTIF('Task 8 tuần'!$B$2:$B$217,2) -> 29 | D12: =COUNTIF('Task 8 tuần'!$B$2:$B$217,3) -> 29 | E12: =COUNTIF('Task 8 tuần'!$B$2:$B$217,4) -> 30 | F12: =COUNTIF('Task 8 tuần'!$B$2:$B$217,5) -> 25 | G12: =COUNTIF('Task 8 tuần'!$B$2:$B$217,6) -> 27 | H12: =COUNTIF('Task 8 tuần'!$B$2:$B$217,7) -> 23 | I12: =COUNTIF('Task 8 tuần'!$B$2:$B$217,8) -> 26 | J12: =SUM(B12:I12) -> 216
B13: Tuần 1 | C13: Tuần 2 | D13: Tuần 3 | E13: Tuần 4 | F13: Tuần 5 | G13: Tuần 6 | H13: Tuần 7 | I13: Tuần 8

Sheet Phủ FR-NFR
A1: MA TRẬN PHỦ YÊU CẦU: mỗi FR/NFR phải có ít nhất một task
A2: Cột 'Số task' dùng công thức đếm trên cột tham chiếu; cột 'Task phụ trách' là danh sách ID (sinh từ dữ liệu kế hoạch).
A4: Yêu cầu | B4: Nhóm | C4: Số task | D4: Trạng thái | E4: Task phụ trách
A5: FR-1 | B5: Chức năng | C5: =COUNTIF('Task 8 tuần'!$L$2:$L$217,"*,"&A5&",*") -> 8 | D5: =IF(C5>0,"Có","THIẾU") -> Có | E5: W1-M2-2, W1-M5-2, W2-M2-1, W2-M2-2, W2-M2-4, W2-M5-1, W2-M5-2, W7-M3-2
A6: FR-2 | B6: Chức năng | C6: =COUNTIF('Task 8 tuần'!$L$2:$L$217,"*,"&A6&",*") -> 6 | D6: =IF(C6>0,"Có","THIẾU") -> Có | E6: W1-M2-2, W1-M5-2, W2-M5-1, W3-M2-2, W3-M5-1, W7-M3-2
A7: FR-3 | B7: Chức năng | C7: =COUNTIF('Task 8 tuần'!$L$2:$L$217,"*,"&A7&",*") -> 10 | D7: =IF(C7>0,"Có","THIẾU") -> Có | E7: W1-M2-2, W1-M4-2, W1-M5-2, W2-M4-1, W2-M5-1, W3-M4-2, W3-M5-3, W3-M5-4, W4-M5-1, W7-M3-2
A8: FR-4 | B8: Chức năng | C8: =COUNTIF('Task 8 tuần'!$L$2:$L$217,"*,"&A8&",*") -> 6 | D8: =IF(C8>0,"Có","THIẾU") -> Có | E8: W1-M2-2, W1-M5-2, W2-M5-1, W3-M4-1, W4-M5-1, W7-M3-2
A9: FR-5 | B9: Chức năng | C9: =COUNTIF('Task 8 tuần'!$L$2:$L$217,"*,"&A9&",*") -> 7 | D9: =IF(C9>0,"Có","THIẾU") -> Có | E9: W1-M2-2, W1-M5-2, W2-M5-1, W3-M4-2, W4-M2-3, W4-M5-1, W7-M3-2
A10: FR-6 | B10: Chức năng | C10: =COUNTIF('Task 8 tuần'!$L$2:$L$217,"*,"&A10&",*") -> 7 | D10: =IF(C10>0,"Có","THIẾU") -> Có | E10: W1-M2-2, W1-M5-2, W2-M5-1, W3-M5-2, W4-M2-2, W4-M5-4, W7-M3-2
A11: FR-7 | B11: Chức năng | C11: =COUNTIF('Task 8 tuần'!$L$2:$L$217,"*,"&A11&",*") -> 6 | D11: =IF(C11>0,"Có","THIẾU") -> Có | E11: W1-M2-2, W1-M5-2, W2-M5-1, W4-M1-1, W4-M5-5, W7-M3-2
A12: FR-8 | B12: Chức năng | C12: =COUNTIF('Task 8 tuần'!$L$2:$L$217,"*,"&A12&",*") -> 6 | D12: =IF(C12>0,"Có","THIẾU") -> Có | E12: W1-M2-2, W1-M5-2, W2-M3-1, W2-M5-1, W2-M5-5, W7-M3-2
A13: FR-9 | B13: Chức năng | C13: =COUNTIF('Task 8 tuần'!$L$2:$L$217,"*,"&A13&",*") -> 9 | D13: =IF(C13>0,"Có","THIẾU") -> Có | E13: W1-M2-2, W1-M5-2, W2-M5-1, W3-M5-5, W4-M3-1, W4-M3-2, W4-M3-3, W4-M5-6, W7-M3-2
A14: FR-10 | B14: Chức năng | C14: =COUNTIF('Task 8 tuần'!$L$2:$L$217,"*,"&A14&",*") -> 6 | D14: =IF(C14>0,"Có","THIẾU") -> Có | E14: W1-M2-2, W1-M5-2, W2-M5-1, W5-M3-1, W5-M3-4, W7-M3-2
A15: FR-11 | B15: Chức năng | C15: =COUNTIF('Task 8 tuần'!$L$2:$L$217,"*,"&A15&",*") -> 10 | D15: =IF(C15>0,"Có","THIẾU") -> Có | E15: W1-M2-2, W1-M5-2, W2-M5-1, W3-M2-5, W3-M3-1, W3-M3-2, W3-M3-4, W5-M3-2, W5-M5-1, W7-M3-2
A16: FR-12 | B16: Chức năng | C16: =COUNTIF('Task 8 tuần'!$L$2:$L$217,"*,"&A16&",*") -> 8 | D16: =IF(C16>0,"Có","THIẾU") -> Có | E16: W1-M2-2, W1-M5-2, W2-M5-1, W3-M3-1, W3-M3-3, W5-M3-3, W5-M5-1, W7-M3-2
... A66: NFR-23 | B66: Phi chức năng | C66: =COUNTIF('Task 8 tuần'!$L$2:$L$217,"*,"&A66&",*") -> 6 | D66: =IF(C66>0,"Có","THIẾU") -> Có | E66: W1-M3-4, W2-M4-2, W3-M1-2, W3-M4-3, W6-M4-3, W7-M4-2
A68: Yêu cầu còn thiếu | C68: =COUNTIF(D5:D66,"THIẾU") -> 0

Sheet Jira Import
A1: Summary | B1: Issue Type | C1: Parent (Epic key) | D1: Epic (tên) | E1: Original Estimate | F1: Labels | G1: Labels | H1: Sprint | I1: Description
A2: [W1][M1] Confluence space, template, DoD | B2: Task | C2: SCRUM-14 | D2: E14 - Documentation | E2: 5h | F2: W1 | G2: M1 | H2: Sprint 1 - Nền móng | I2: Mục tiêu/Tiêu chí hoàn thành: - Cây 7 thư mục; template trang; DoD đã đăng và cả nhóm đã đọc Yêu cầu liên quan: — Cần trước: — ID kế hoạch: W1-M1-3
A3: [W1][M1] Architecture v0.1: sơ đồ SOA/microservice, ranh giới service, ADR 001→010 | B3: Task | C3: SCRUM-14 | D3: E14 - Documentation | E3: 14h | F3: W1 | G3: M1 | H3: Sprint 1 - Nền móng | I3: Mục tiêu/Tiêu chí hoàn thành: - Sơ đồ + 10 ADR trên Confluence, nhóm thống nhất Yêu cầu liên quan: NFR-7,NFR-17 Cần trước: — ID kế hoạch: W1-M1-4
A4: [W1][M1] docker-compose hạ tầng: Postgres, Mongo, RabbitMQ, NiFi | B4: Task | C4: SCRUM-1 | D4: E1 - Platform/DevOps | E4: 10h | F4: W1 | G4: M1 | H4: Sprint 1 - Nền móng | I4: Mục tiêu/Tiêu chí hoàn thành: - docker compose up chạy đủ 4 thành phần; ghi rõ RAM tối thiểu VPS (khuyến nghị 16GB) Yêu cầu liên quan: NFR-7 Cần trước: — ID kế hoạch: W1-M1-5
A5: [W1][M1] Template service .NET (Clean Architecture, health check, Serilog, Swagger, Dockerfile) | B5: Task | C5: SCRUM-1 | D5: E1 - Platform/DevOps | E5: 9h | F5: W1 | G5: M1 | H5: Sprint 1 - Nền móng | I5: Mục tiêu/Tiêu chí hoàn thành: - Clone về chạy được trong 10 phút; có /health, Swagger, Dockerfile Yêu cầu liên quan: NFR-17 Cần trước: — ID kế hoạch: W1-M1-6
A6: [W1][M2] Glossary và domain model | B6: Task | C6: SCRUM-14 | D6: E14 - Documentation | E6: 8h | F6: W1 | G6: M2 | H6: Sprint 1 - Nền móng | I6: Mục tiêu/Tiêu chí hoàn thành: - ≥30 thuật ngữ; chốt quy tắc OCT (nhận upload, chỉ Fundus được AI chấm) Yêu cầu liên quan: — Cần trước: — ID kế hoạch: W1-M2-1
A7: [W1][M2] Use case spec Patient, Doctor (FR-1→21) | B7: Task | C7: SCRUM-14 | D7: E14 - Documentation | E7: 14h | F7: W1 | G7: M2 | H7: Sprint 1 - Nền móng | I7: Mục tiêu/Tiêu chí hoàn thành: - Mỗi FR có use case, luồng chính, luồng ngoại lệ Yêu cầu liên quan: FR-1:21 Cần trước: — ID kế hoạch: W1-M2-2
A8: [W1][M2] Class diagram miền v0.1 | B8: Task | C8: SCRUM-14 | D8: E14 - Documentation | E8: 10h | F8: W1 | G8: M2 | H8: Sprint 1 - Nền móng | I8: Mục tiêu/Tiêu chí hoàn thành: - Account kế thừa 4 vai trò; Clinic, Analysis, Review, Report; đúng UML 2.0 Yêu cầu liên quan: — Cần trước: — ID kế hoạch: W1-M2-3
A9: [W1][M2] State diagram AnalysisRequest + Activity diagram luồng sàng lọc | B9: Task | C9: SCRUM-4 | D9: E4 - Analysis Pipeline | E9: 8h | F9: W1 | G9: M2 | H9: Sprint 1 - Nền móng | I9: Mục tiêu/Tiêu chí hoàn thành: - Đủ trạng thái Pending→Processing→AIDone→Reviewed→Finalized/Failed Yêu cầu liên quan: FR-24 Cần trước: — ID kế hoạch: W1-M2-4
A10: [W1][M2] ERD Profile/Analysis | B10: Task | C10: SCRUM-4 | D10: E4 - Analysis Pipeline | E10: 12h | F10: W1 | G10: M2 | H10: Sprint 1 - Nền móng | I10: Mục tiêu/Tiêu chí hoàn thành: - Schema tách theo service, không khóa ngoại chéo service Yêu cầu liên quan: — Cần trước: — ID kế hoạch: W1-M2-5
A11: [W1][M3] Chuẩn hóa FR/NFR, sửa lỗi FR-30, ma trận truy vết, MoSCoW | B11: Task | C11: SCRUM-14 | D11: E14 - Documentation | E11: 10h | F11: W1 | G11: M3 | H11: Sprint 1 - Nền móng | I11: Mục tiêu/Tiêu chí hoàn thành: - Ma trận FR/NFR↔task; FR-30 ghi đúng; phân loại Must/Should/Could Yêu cầu liên quan: FR-30 Cần trước: — ID kế hoạch: W1-M3-1
A12: [W1][M3] Use case spec Clinic, Admin (FR-22→39) | B12: Task | C12: SCRUM-14 | D12: E14 - Documentation | E12: 14h | F12: W1 | G12: M3 | H12: Sprint 1 - Nền móng | I12: Mục tiêu/Tiêu chí hoàn thành: - Mỗi FR có use case Yêu cầu liên quan: FR-22:39 Cần trước: — ID kế hoạch: W1-M3-2
... A215: [W8][M5] Kiểm tra giao diện trên 3 thiết bị | B215: Task | C215: SCRUM-13 | D215: E13 - Testing | E215: 8h | F215: W8 | G215: M5 | H215: Sprint 8 - Ổn định, Tài liệu, Bảo vệ | I215: Mục tiêu/Tiêu chí hoàn thành: - Desktop, tablet, mobile đều ổn Yêu cầu liên quan: NFR-13 Cần trước: — ID kế hoạch: W8-M5-5
A217: Ghi chú: (1) Bỏ SCRUM-15, SCRUM-16 đã tạo tay. (2) Cột Parent giả định Epic E1→E14 là SCRUM-1→SCRUM-14, hãy kiểm tra lại số khóa trên board. (3) Nếu Jira báo lỗi định dạng Original Estimate, đổi sang giây (giờ × 3600). (4) Nếu không import được Sprint, tạo task rồi kéo vào sprint.

Sheet Lịch Sprint
A1: Sprint | B1: Tên | C1: Bắt đầu (MM/DD/YYYY) | D1: Kết thúc (MM/DD/YYYY) | E1: Mục tiêu
A2: 1 | B2: Sprint 1 - Nền móng | C2: 10/05/2026 | D2: 10/11/2026 | E2: Chốt phạm vi, dựng công cụ, SRS v0.1, kiến trúc v0.1, hợp đồng API AI
A3: 2 | B3: Sprint 2 - Gateway, Identity, Profile, AI v0.1 | C3: 10/12/2026 | D3: 10/18/2026 | E3: Đăng nhập qua Gateway trên staging HTTPS; hồ sơ/clinic; AI v0.1
A4: 3 | B4: Sprint 3 - Luồng phân tích | C4: 10/19/2026 | D4: 10/25/2026 | E4: Upload→Queue→AI→Kết quả; Billing trừ credit
A5: 4 | B5: Sprint 4 - MVP | C5: 10/26/2026 | D5: 11/01/2026 | E5: MVP: upload→AI→FCM→bác sĩ review→PDF (≥50% FR)
A6: 5 | B6: Sprint 5 - Chat, Thanh toán, Batch, Bảo mật | C6: 11/02/2026 | D6: 11/08/2026 | E6: Chat, VNPay sandbox, batch 100 ảnh, bảo mật, NiFi #2
A7: 6 | B7: Sprint 6 - Admin, Analytics, Freeze | C7: 11/09/2026 | D7: 11/15/2026 | E7: Admin, analytics-svc, NiFi #3, đủ 39 FR, feature freeze
A8: 7 | B8: Sprint 7 - Test, Hiệu năng, Production | C8: 11/16/2026 | D8: 11/22/2026 | E8: Test, hiệu năng, production, release candidate
A9: 8 | B9: Sprint 8 - Ổn định, Tài liệu, Bảo vệ | C9: 11/23/2026 | D9: 11/29/2026 | E9: v1.0.0, tài liệu cuối, vấn đáp
